Workbook

Sheet encabezado
A1: Consecutivo 1 | B1: Cédula/NIT propietario | C1: Nombre productor | D1: 1.1 Año | E1: 1. Periodo declarado | F1: 23. Total a pagar ($ COP) | I1: Estado Pago | J1: Fecha de presentación | K1: Fecha Pago
A2: 24777 | B2: 800204226 | C2: GENETICA BIOS SAS | D2: 2026 | E2: Bimestre 01 (ene-feb) | F2: 90000 | G2: =SUMIFS(detalles!F:F,detalles!A:A,A2) -> 90000 | H2: =F2-G2 -> 0 | I2: ✓ Pago realizado | J2: 2026-03-16 14:42:12.571 | K2: 2026-03-17 08:41:42.605
A3: 24833 | B3: 901326859 | C3: MMI LATAM SAS | D3: 2026 | E3: Bimestre 01 (ene-feb) | F3: 43000 | G3: =SUMIFS(detalles!F:F,detalles!A:A,A3) -> 43000 | H3: =F3-G3 -> 0 | I3: ✓ Pago realizado | J3: 2026-03-16 17:27:50.037 | K3: 2026-03-17 08:01:55.417
A4: 24851 | B4: 890906388 | C4: PROCOPALSA | D4: 2026 | E4: Bimestre 01 (ene-feb) | F4: 1624000 | G4: =SUMIFS(detalles!F:F,detalles!A:A,A4) -> 1624000 | H4: =F4-G4 -> 0 | I4: ✓ Pago realizado | J4: 2026-03-17 08:13:47.755 | K4: 2026-03-17 08:18:07.808
A5: 24844 | B5: 890932539 | C5: MIRO SEGURIDAD LTDA | D5: 2025 | E5: Bimestre 01 (ene-feb) | F5: 1144000 | G5: =SUMIFS(detalles!F:F,detalles!A:A,A5) -> 1144000 | H5: =F5-G5 -> 0 | I5: ✓ Pago realizado | J5: 2026-03-16 19:55:32.074 | K5: 2026-03-17 09:14:06.977
A6: 24862 | B6: 900557608 | C6: COMERCIALIZADORA INSUASEO SAS | D6: 2026 | E6: Bimestre 01 (ene-feb) | F6: 7400 | G6: =SUMIFS(detalles!F:F,detalles!A:A,A6) -> 7400 | H6: =F6-G6 -> 0 | I6: ✓ Pago realizado | J6: 2026-03-17 09:27:15.920 | K6: 2026-03-17 09:28:47.044
A7: 24864 | B7: 901370476 | C7: NEXUS GESTION INTEGRAL SAS | D7: 2026 | E7: Bimestre 01 (ene-feb) | F7: 2424071 | G7: =SUMIFS(detalles!F:F,detalles!A:A,A7) -> 2424071 | H7: =F7-G7 -> 0 | I7: ✓ Pago realizado | J7: 2026-03-17 09:34:00.420 | K7: 2026-03-17 09:40:09.517
A8: 24867 | B8: 900963711 | C8: NATUBIOTICS CORP SAS | D8: 2025 | E8: Bimestre 06 (nov-dic) | F8: 262000 | G8: =SUMIFS(detalles!F:F,detalles!A:A,A8) -> 262000 | H8: =F8-G8 -> 0 | I8: ✓ Pago realizado | J8: 2026-03-17 09:37:32.421 | K8: 2026-03-17 09:41:40.037
A9: 24869 | B9: 811007506 | C9: PERYSA S.A.S | D9: 2026 | E9: Bimestre 01 (ene-feb) | F9: 609000 | G9: =SUMIFS(detalles!F:F,detalles!A:A,A9) -> 609000 | H9: =F9-G9 -> 0 | I9: ✓ Pago realizado | J9: 2026-03-17 09:38:07.719 | K9: 2026-03-17 09:44:18.516
A10: 24837 | B10: 830096376 | C10: TRANSPORTES HUMADEA SAS | D10: 2026 | E10: Bimestre 01 (ene-feb) | F10: 22000 | G10: =SUMIFS(detalles!F:F,detalles!A:A,A10) -> 22000 | H10: =F10-G10 -> 0 | I10: ✓ Pago realizado | J10: 2026-03-16 18:22:14.584 | K10: 2026-03-17 10:41:53.224
A11: 24876 | B11: 9005849763 | C11: DANIEL ALEJANDRO QUINTERO OSSA | D11: 2026 | E11: Bimestre 01 (ene-feb) | F11: 47000 | G11: =SUMIFS(detalles!F:F,detalles!A:A,A11) -> 47000 | H11: =F11-G11 -> 0 | I11: ✓ Pago realizado | J11: 2026-03-17 09:53:14.411 | K11: 2026-03-17 10:26:53.307
A12: 24887 | B12: 901095278 | C12: BKCOL SAS | D12: 2026 | E12: Bimestre 01 (ene-feb) | F12: 31000 | G12: =SUMIFS(detalles!F:F,detalles!A:A,A12) -> 31000 | H12: =F12-G12 -> 0 | I12: ✓ Pago realizado | J12: 2026-03-17 10:31:06.551 | K12: 2026-03-17 10:47:27.953
A13: 24858 | B13: 900239116 | C13: INDUSTRIAS ALIMENTICIAS JARAMILLO VELEZ SAS | D13: 2026 | E13: Bimestre 01 (ene-feb) | F13: 945646 | G13: =SUMIFS(detalles!F:F,detalles!A:A,A13) -> 945646 | H13: =F13-G13 -> 0 | I13: ✓ Pago realizado | J13: 2026-03-17 08:52:13.744 | K13: 2026-03-17 10:31:53.459
... A69: 24846 | B69: 800098726 | C69: INVERSIONES JUANFE S.A.S | D69: 2026 | E69: Bimestre 01 (ene-feb) | F69: 109065 | G69: =SUMIFS(detalles!F:F,detalles!A:A,A69) -> 109065 | H69: =F69-G69 -> 0 | I69: ✓ Pago realizado | J69: 2026-03-16 21:52:34.081 | K69: 2026-03-17 20:13:41.926

Sheet detalles
A1: Consecutivo | B1: Cédula/NIT propietario | C1: Nombre productor | D1: CODIGO | E1: DESCRIPCION | F1: VALOR
A2: 24713 | B2: 900191058 | C2: INVERSIONES MERCAVENTAS SAS | D2: 7377 | E2: Retención por industria y comercio | F2: 488897
A3: 24746 | B3: 860007738 | C3: BANCO POPULAR S.A | D3: 7377 | E3: Retención por industria y comercio | F3: 1198000
A4: 24777 | B4: 800204226 | C4: GENETICA BIOS SAS | D4: 7377 | E4: Retención por industria y comercio | F4: 90000
A5: 24783 | B5: 901655409 | C5: COSMO EDUCATION SAS | D5: 7377 | E5: Retención por industria y comercio | F5: 121350
A6: 24821 | B6: 890921157 | C6: MARROCAR SAS | D6: 7377 | E6: Retención por industria y comercio | F6: 2000
A7: 24833 | B7: 901326859 | C7: MMI LATAM SAS | D7: 7377 | E7: Retención por industria y comercio | F7: 43000
A8: 24837 | B8: 830096376 | C8: TRANSPORTES HUMADEA SAS | D8: 7377 | E8: Retención por industria y comercio | F8: 22000
A9: 24839 | B9: 900623074 | C9: CEM ELECTRONIX S.A.S | D9: 7377 | E9: Retención por industria y comercio | F9: 41079
A10: 24844 | B10: 890932539 | C10: MIRO SEGURIDAD LTDA | D10: 7377 | E10: Retención por industria y comercio | F10: 1144000
A11: 24845 | B11: 901400246 | C11: IDEANDO NEGOCIOS SAS | D11: 7377 | E11: Retención por industria y comercio | F11: 51000
A12: 24846 | B12: 800098726 | C12: INVERSIONES JUANFE S.A.S | D12: 7377 | E12: Retención por industria y comercio | F12: 109065
A13: 24847 | B13: 900883396 | C13: soluciones redy sas | D13: 7377 | E13: Retención por industria y comercio | F13: 5010
... A17: 24858 | B17: 900239116 | C17: INDUSTRIAS ALIMENTICIAS JARAMILLO VELEZ SAS | D17: 7377 | E17: Retención por industria y comercio | F17: 996676
A18: 24858 | B18: 900239116 | C18: INDUSTRIAS ALIMENTICIAS JARAMILLO VELEZ SAS | E18: RETENCION PRACTICADA EN EXCESO | F18: -51030
A19: 24859 | B19: 900084859 | C19: NUTRISER COLOMBIA SAS | D19: 7377 | E19: Retención por industria y comercio | F19: 7000
A20: 24860 | B20: 830002655 | C20: INTERWORLD FREIGHT SAS | D20: 7377 | E20: Retención por industria y comercio | F20: 34000
A21: 24862 | B21: 900557608 | C21: COMERCIALIZADORA INSUASEO SAS | D21: 7377 | E21: Retención por industria y comercio | F21: 7400
A22: 24863 | B22: 900155107 | C22: CENCOSUD COLOMBIA SA | D22: 7377 | E22: Retención por industria y comercio | F22: 2502000
A23: 24864 | B23: 901370476 | C23: NEXUS GESTION INTEGRAL SAS | D23: 7377 | E23: Retención por industria y comercio | F23: 2424071
A24: 24866 | B24: 860007336 | C24: CAJA COLOMBIANA DE SUBSIDIO FAMILIAR COLSUBSIDIO | D24: 7377 | E24: Retención por industria y comercio | F24: 931000
A25: 24867 | B25: 900963711 | C25: NATUBIOTICS CORP SAS | D25: 7378 | E25: Sanción RETEICA | F25: 262000
A26: 24869 | B26: 811007506 | C26: PERYSA S.A.S | D26: 7377 | E26: Retención por industria y comercio | F26: 609000
A27: 24870 | B27: 900068426 | C27: OPL CARGA SAS | D27: 7377 | E27: Retención por industria y comercio | F27: 356000
A28: 24874 | B28: 811041448 | C28: BH SALUD SAS | D28: 7377 | E28: Retención por industria y comercio | F28: 1492595
A29: 24876 | B29: 9005849763 | C29: DANIEL ALEJANDRO QUINTERO OSSA | D29: 7377 | E29: Retención por industria y comercio | F29: 47000
A30: 24880 | B30: 800060276 | C30: DIVITEX S.A.S | D30: 7377 | E30: Retención por industria y comercio | F30: 774260
... A51: 24935 | B51: 900642557 | C51: INVERSIONES VAQUITA EXPRESS SAS | D51: 7377 | E51: Retención por industria y comercio | F51: 7181208
A52: 24935 | B52: 900642557 | C52: INVERSIONES VAQUITA EXPRESS SAS | E52: RETENCION PRACTICADA EN EXCESO | F52: -45430
A53: 24936 | B53: 900195166 | C53: Crearcimientos Propiedad Raíz SAS | D53: 7377 | E53: Retención por industria y comercio | F53: 6555496
A54: 24938 | B54: 860000656 | C54: HMV INGENIEROS LTDA | D54: 7377 | E54: Retención por industria y comercio | F54: 101000
A55: 24939 | B55: 890500726 | C55: COLGAS S.A.E.S.P | D55: 7377 | E55: Retención por industria y comercio | F55: 68000
A56: 24941 | B56: 890902916 | C56: UNION ISRAELITA DE BENEFICENCIA | D56: 7377 | E56: Retención por industria y comercio | F56: 2293000
A57: 24948 | B57: 901580486 | C57: ICOEXPANDIDOS S.A.S. | D57: 7377 | E57: Retención por industria y comercio | F57: 9711000
A58: 24951 | B58: 891700037 | C58: MAPFRE SEGUROS GENERALES DE COLOMBIA SA | D58: 7377 | E58: Retención por industria y comercio | F58: 1083000
A59: 24952 | B59: 860035827 | C59: BANCO COMERCIAL AV VILLAS S.A | D59: 7377 | E59: Retención por industria y comercio | F59: 430000
A60: 24954 | B60: 900784477 | C60: DENTOMAT SAS | D60: 7377 | E60: Retención por industria y comercio | F60: 48000
A61: 24955 | B61: 890900016 | C61: AGENCIA DE AUTOMOVILES S.A. Ó AGENCIAUTO | D61: 7377 | E61: Retención por industria y comercio | F61: 15000
A62: 24956 | B62: 900791257 | C62: SMYM LOGISTICA SAS | D62: 7377 | E62: Retención por industria y comercio | F62: 14240
A63: 24957 | B63: 900315057 | C63: CONSTRUCTORA CONARTE SA | D63: 7377 | E63: Retención por industria y comercio | F63: 4838929
...
